2021-04-24 09:42:39,282 INFO    MainThread:9080 [internal.py:wandb_internal():91] W&B internal server running at pid: 9080, started at: 2021-04-24 09:42:39.282318
2021-04-24 09:42:39,285 DEBUG   SenderThread:9080 [sender.py:send():160] send: header
2021-04-24 09:42:39,285 INFO    WriterThread:9080 [datastore.py:open_for_write():77] open: /home/arora/kaggle/shopee/src/wandb/run-20210424_094238-1kzhigyi/run-1kzhigyi.wandb
2021-04-24 09:42:39,285 DEBUG   HandlerThread:9080 [handler.py:handle_request():120] handle_request: check_version
2021-04-24 09:42:39,286 DEBUG   SenderThread:9080 [sender.py:send():160] send: request
2021-04-24 09:42:39,286 DEBUG   SenderThread:9080 [sender.py:send_request():169] send_request: check_version
2021-04-24 09:42:39,349 DEBUG   SenderThread:9080 [sender.py:send():160] send: run
2021-04-24 09:42:39,350 DEBUG   SenderThread:9080 [git.py:repo():33] git repository is invalid
2021-04-24 09:42:39,403 INFO    SenderThread:9080 [sender.py:_start_run_threads():654] run started: 1kzhigyi with start time 1619257358
2021-04-24 09:42:39,403 DEBUG   SenderThread:9080 [sender.py:send():160] send: summary
2021-04-24 09:42:39,403 INFO    SenderThread:9080 [sender.py:_save_file():781] saving file wandb-summary.json with policy end
2021-04-24 09:42:39,403 DEBUG   HandlerThread:9080 [handler.py:handle_request():120] handle_request: run_start
2021-04-24 09:42:39,408 DEBUG   HandlerThread:9080 [meta.py:__init__():39] meta init
2021-04-24 09:42:39,408 DEBUG   HandlerThread:9080 [meta.py:__init__():53] meta init done
2021-04-24 09:42:39,408 DEBUG   HandlerThread:9080 [meta.py:probe():210] probe
2021-04-24 09:42:39,415 DEBUG   HandlerThread:9080 [git.py:repo():33] git repository is invalid
2021-04-24 09:42:39,415 DEBUG   HandlerThread:9080 [meta.py:_save_pip():57] save pip
2021-04-24 09:42:39,415 DEBUG   HandlerThread:9080 [meta.py:_save_pip():71] save pip done
2021-04-24 09:42:39,415 DEBUG   HandlerThread:9080 [meta.py:_save_conda():78] save conda
2021-04-24 09:42:39,418 ERROR   HandlerThread:9080 [meta.py:_save_conda():85] Error saving conda packages
Traceback (most recent call last):
  File "/home/arora/.local/lib/python3.7/site-packages/wandb/sdk/internal/meta.py", line 83, in _save_conda
    subprocess.call(["conda", "env", "export"], stdout=f)
  File "/opt/conda/envs/rapids-0.18/lib/python3.7/subprocess.py", line 339, in call
    with Popen(*popenargs, **kwargs) as p:
  File "/opt/conda/envs/rapids-0.18/lib/python3.7/subprocess.py", line 800, in __init__
    restore_signals, start_new_session)
  File "/opt/conda/envs/rapids-0.18/lib/python3.7/subprocess.py", line 1551, in _execute_child
    raise child_exception_type(errno_num, err_msg, err_filename)
FileNotFoundError: [Errno 2] No such file or directory: 'conda': 'conda'
2021-04-24 09:42:39,419 DEBUG   HandlerThread:9080 [meta.py:_save_conda():86] save conda done
2021-04-24 09:42:39,419 DEBUG   HandlerThread:9080 [meta.py:probe():252] probe done
2021-04-24 09:42:39,423 DEBUG   SenderThread:9080 [sender.py:send():160] send: files
2021-04-24 09:42:39,423 INFO    SenderThread:9080 [sender.py:_save_file():781] saving file wandb-metadata.json with policy now
2021-04-24 09:42:39,429 DEBUG   HandlerThread:9080 [handler.py:handle_request():120] handle_request: status
2021-04-24 09:42:39,429 DEBUG   SenderThread:9080 [sender.py:send():160] send: request
2021-04-24 09:42:39,429 DEBUG   SenderThread:9080 [sender.py:send_request():169] send_request: status
2021-04-24 09:42:55,513 DEBUG   HandlerThread:9080 [handler.py:handle_request():120] handle_request: status
2021-04-24 09:42:55,514 DEBUG   SenderThread:9080 [sender.py:send():160] send: request
2021-04-24 09:42:55,514 DEBUG   SenderThread:9080 [sender.py:send_request():169] send_request: status
2021-04-24 09:42:56,442 WARNING MainThread:9080 [internal.py:wandb_internal():146] Internal process interrupt: 1
2021-04-24 09:42:56,673 WARNING MainThread:9080 [internal.py:wandb_internal():146] Internal process interrupt: 2
2021-04-24 09:42:56,674 ERROR   MainThread:9080 [internal.py:wandb_internal():149] Internal process interrupted.
2021-04-24 09:42:57,456 INFO    WriterThread:9080 [datastore.py:close():258] close: /home/arora/kaggle/shopee/src/wandb/run-20210424_094238-1kzhigyi/run-1kzhigyi.wandb
2021-04-24 09:42:57,515 INFO    HandlerThread:9080 [handler.py:finish():624] shutting down handler
2021-04-24 09:42:57,544 INFO    SenderThread:9080 [sender.py:finish():884] shutting down sender
2021-04-24 09:42:58,934 INFO    MainThread:9080 [internal.py:handle_exit():78] Internal process exited
